Workbook

Sheet Statistiques
A1: Force | B1: Habileté | C1: Mental | D1: Magie/Cosmique | E1: Total Points | G1: HP | H1: HP (normal) | I1: HP (transcendant)
A2: 20 | B2: 2 | C2: 5 | D2: 2 | E2: =SUM(A2:D2) -> 29 | G2: =H2+I2 -> 6245 | H2: =10 + CEILING(MIN(A2,16)*75 + MIN(D2,16)*5 + MIN(C2,16)*45, 1) -> 1445 | I2: =CEILING(MAX(A2-16,0)^2*300 + MAX(D2-16,0)^2*25 + MAX(C2-16,0)^2*175,1) -> 4800
A3: 20 AD | B3: 10 AD | C3: 5 AD | E3: 27 | G3: Mana | H3: Mana (normal) | I3: Mana (transcendant)
B4: 10 AP | C4: 5 AP | D4: 20 AP | G4: =H4+I4 -> 350 | H4: =10 + CEILING(MIN(B2,16)*20 + MIN(D2,16)*75 + MIN(C2,16)*30, 1) -> 350 | I4: =CEILING(MAX(D2-16,0)^2*300 + MAX(B2-16,0)^2*80 + MAX(C2-16,0)^2*120,1) -> 0
A5: 75 HP | C5: 45 HP | D5: 5 HP | G5: AD | H5: AD (normal) | I5: AD (transcendant)
B6: 20 Mana | C6: 30 Mana | D6: 75 Mana | G6: =H6+I6 -> 3125 | H6: =CEILING(MIN(A2,16)*20 + MIN(B2,16)*10 + MIN(C2,16)*5, 1) -> 365 | I6: =CEILING(MAX(A2-16,0)^2*172.5 + MAX(B2-16,0)^2*86.25 + MAX(C2-16,0)^2*28.75,1) -> 2760
B7: 5% Crit | G7: AP | H7: AP (normal) | I7: AP (transcendant)
B8: 2-3% Sapience | G8: =H8+I8 -> 85 | H8: =CEILING(MIN(B2,16)*10 + MIN(D2,16)*20 + MIN(C2,16)*5, 1) -> 85 | I8: =CEILING(MAX(D2-16,0)^2*172.5 + MAX(B2-16,0)^2*86.25 + MAX(C2-16,0)^2*28.75,1) -> 0
A9: 2% D. Crit | B9: 5% D. Crit | D9: 2% D. Crit | G9: Armure | H9: Armure (normal) | I9: Armure (transcendant)
A10: 4-5 Armure | B10: 1 Armure | C10: 6 Armure | G10: =H10+I10 -> 328 | H10: =CEILING(MIN(A2,16)*4.5 + MIN(B2,16)*1 + MIN(C2,16)*6, 1) -> 104 | I10: =CEILING(MAX(A2-16,0)^2*14 + MAX(C2-16,0)^2*20 + MAX(B2-16,0)^2*2,1) -> 224
B11: 1 Rés. Mag. | C11: 6 Rés. Mag | D11: 4-5 Rés. Mag. | G11: Rés. Mag | H11: Rés. Mag (normal) | I11: Rés. Mag (transcendant)
G12: =H12+I12 -> 41 | H12: =CEILING(MIN(B2,16)*1 + MIN(D2,16)*4.5 + MIN(C2,16)*6, 1) -> 41 | I12: =CEILING(MAX(D2-16,0)^2*14 + MAX(C2-16,0)^2*20 + MAX(B2-16,0)^2*2,1) -> 0
A13: Niveau | B13: Points gagnés | C13: Total des points | D13: Limite stats | G13: % Crit | H13: % Crit (normal)
A14: 1 | B14: 10 (départ) | C14: 10 | D14: 5 | G14: =H14 -> 15 | H14: =5 + CEILING(MIN(B2,20)*5, 1) -> 15
A15: 2 | B15: 1 | C15: 11 | D15: 6 | G15: % D. Crit | H15: % D. Crit (normal) | I15: % D. Crit (transcendant)
A16: 3 | B16: 1 | C16: 12 | D16: 7 | G16: =H16+I16 -> 250 | H16: =150 + CEILING(MIN(A2,16)*2 + MIN(D2,16)*2 + MIN(B2,16)*5, 1) -> 196 | I16: =CEILING(MAX(A2-16,0)^2*(3+(1/3)) + MAX(D2-16,0)^2*(3+(1/3)) + MAX(B2-16,0)^2*(8+(1/3)),1) -> 54
A17: 4 | B17: 2 | C17: 14 | D17: 8 | G17: Sapience | H17: Sapience (normal) | I17: Sapience (transcendant)
A18: 5 | B18: 1 | C18: 15 | D18: 9 | G18: =H18 -> 5 | H18: =CEILING(MIN(B2,16)*2.5, 1) -> 5
A19: 6 | B19: 2 | C19: 17 | D19: 10
A20: 7 | B20: 1 | C20: 18 | D20: 11
A21: 8 | B21: 1 | C21: 19 | D21: 12
A22: 9 | B22: 2 | C22: 21 | D22: 13
A23: 10 | B23: 1 | C23: 22 | D23: 14
A24: 11 | B24: 1 | C24: 23 | D24: 15
A25: 12 | B25: 2 | C25: 25 | D25: 16
A26: 13 | B26: 1 | C26: 26 | D26: 16
A27: 14 | B27: 1 | C27: 27 | D27: 16
A28: 15 | B28: 2 | C28: 29 | D28: 16
A29: 16 | B29: 1 | C29: 30 | D29: 16
A30: 17 | B30: 1 | C30: 31 | D30: 16
A31: 18 | B31: 2 | C31: 33 | D31: 16

Sheet Runes

Sheet Stats Erwan
A1: Force | B1: Habileté | C1: Mental | D1: Magie/Cosmique | E1: Total Points | G1: HP | H1: HP (normal) | I1: HP (transcendant)
A2: 3 | B2: 6 | C2: 1 | D2: 2 | E2: =SUM(A2:D2) -> 12 | G2: =H2+I2 -> 290 | H2: =10 + CEILING(MIN(A2,16)*75 + MIN(D2,16)*5 + MIN(C2,16)*45, 1) -> 290 | I2: =CEILING(MAX(A2-16,0)^2*300 + MAX(D2-16,0)^2*25 + MAX(C2-16,0)^2*175,1) -> 0
A3: 20 AD | B3: 10 AD | C3: 5 AD | G3: Mana | H3: Mana (normal) | I3: Mana (transcendant)
B4: 10 AP | C4: 5 AP | D4: 20 AP | G4: =H4+I4 -> 310 | H4: =10 + CEILING(MIN(B2,16)*20 + MIN(D2,16)*75 + MIN(C2,16)*30, 1) -> 310 | I4: =CEILING(MAX(D2-16,0)^2*300 + MAX(B2-16,0)^2*80 + MAX(C2-16,0)^2*120,1) -> 0
A5: 75 HP | C5: 45 HP | D5: 5 HP | G5: AD | H5: AD (normal) | I5: AD (transcendant)
B6: 20 Mana | C6: 30 Mana | D6: 75 Mana | G6: =H6+I6 -> 125 | H6: =CEILING(MIN(A2,16)*20 + MIN(B2,16)*10 + MIN(C2,16)*5, 1) -> 125 | I6: =CEILING(MAX(A2-16,0)^2*172.5 + MAX(B2-16,0)^2*86.25 + MAX(C2-16,0)^2*28.75,1) -> 0
B7: 5% Crit | G7: AP | H7: AP (normal) | I7: AP (transcendant)
B8: 2-3% Sapience | G8: =H8+I8 -> 105 | H8: =CEILING(MIN(B2,16)*10 + MIN(D2,16)*20 + MIN(C2,16)*5, 1) -> 105 | I8: =CEILING(MAX(D2-16,0)^2*172.5 + MAX(B2-16,0)^2*86.25 + MAX(C2-16,0)^2*28.75,1) -> 0
A9: 2% D. Crit | B9: 5% D. Crit | D9: 2% D. Crit | G9: Armure | H9: Armure (normal) | I9: Armure (transcendant)
A10: 4-5 Armure | B10: 1 Armure | C10: 6 Armure | G10: =H10+I10 -> 26 | H10: =CEILING(MIN(A2,16)*4.5 + MIN(B2,16)*1 + MIN(C2,16)*6, 1) -> 26 | I10: =CEILING(MAX(A2-16,0)^2*14 + MAX(C2-16,0)^2*20 + MAX(B2-16,0)^2*2,1) -> 0
B11: 1 Rés. Mag. | C11: 6 Rés. Mag | D11: 4-5 Rés. Mag. | G11: Rés. Mag | H11: Rés. Mag (normal) | I11: Rés. Mag (transcendant)
G12: =H12+I12 -> 21 | H12: =CEILING(MIN(B2,16)*1 + MIN(D2,16)*4.5 + MIN(C2,16)*6, 1) -> 21 | I12: =CEILING(MAX(D2-16,0)^2*14 + MAX(C2-16,0)^2*20 + MAX(B2-16,0)^2*2,1) -> 0
A13: Niveau | B13: Points gagnés | C13: Total des points | D13: Limite stats | G13: % Crit | H13: % Crit (normal)
A14: 1 | B14: 10 (départ) | C14: 10 | D14: 5 | G14: =H14 -> 35 | H14: =5 + CEILING(MIN(B2,20)*5, 1) -> 35
A15: 2 | B15: 1 | C15: 11 | D15: 6 | G15: % D. Crit | H15: % D. Crit (normal) | I15: % D. Crit (transcendant)
A16: 3 | B16: 1 | C16: 12 | D16: 7 | G16: =H16+I16 -> 190 | H16: =150 + CEILING(MIN(A2,16)*2 + MIN(D2,16)*2 + MIN(B2,16)*5, 1) -> 190 | I16: =CEILING(MAX(A2-16,0)^2*(3+(1/3)) + MAX(D2-16,0)^2*(3+(1/3)) + MAX(B2-16,0)^2*(8+(1/3)),1) -> 0
A17: 4 | B17: 2 | C17: 14 | D17: 8 | G17: Sapience | H17: Sapience (normal) | I17: Sapience (transcendant)
A18: 5 | B18: 1 | C18: 15 | D18: 9 | G18: =H18 -> 15 | H18: =CEILING(MIN(B2,16)*2.5, 1) -> 15
A19: 6 | B19: 2 | C19: 17 | D19: 10
A20: 7 | B20: 1 | C20: 18 | D20: 11
A21: 8 | B21: 1 | C21: 19 | D21: 12
A22: 9 | B22: 2 | C22: 21 | D22: 13
A23: 10 | B23: 1 | C23: 22 | D23: 14
A24: 11 | B24: 1 | C24: 23 | D24: 15
A25: 12 | B25: 2 | C25: 25 | D25: 16
A26: 13 | B26: 1 | C26: 26 | D26: 16
A27: 14 | B27: 1 | C27: 27 | D27: 16
A28: 15 | B28: 2 | C28: 29 | D28: 16
A29: 16 | B29: 1 | C29: 30 | D29: 16
A30: 17 | B30: 1 | C30: 31 | D30: 16
A31: 18 | B31: 2 | C31: 33 | D31: 16

Sheet Grille Erwan
A1: Colonne 1 | B1: Valeurs stats | C1: Modificateurs | D1: Valeurs max | E1: Valeurs avant buffs/débuffs | F1: Valeurs effectives | G1: Buffs/Débuffs | H1: Colonne 2 | K1: Maîtrise | L1: Catégorie d'arme | M1: Dégâts | N1: 1 cristaux translucide autemant explosife | P1: 1 epee avec effet non identifier | U1: Pièces d'or | V1: 10
A2: HP | B2: ='Stats Erwan'!G2 -> 290 | D2: =B2+C2 -> 290 | E2: 224 | F2: 224 | G2: Miraculé (+50% Soins/Bouclier) | H2: FALSE | K2: TRUE | L2: Dague | M2: 145 | N2: 1 cristaux violet explosif | P2: 2 parchemin qu'on peut pas lire | R2: 10 piece or/arg/cuiv | S2: 1 potion soint mineur 15%+ 15 | U2: Pièces d'argent | V2: 10
A3: Mana | B3: ='Stats Erwan'!G4 -> 310 | D3: =B3+C3 -> 310 | E3: 250 | F3: 250 | G3: Hémorragie (-50% Soins/Bouclier) | H3: FALSE | K3: Physique | L3: 1H | N3: crasse minerale vegetale | S3: 1 potion mana mineur 10%+ 10 | U3: Pièces de cuivre | V3: 10
A4: Bouclier | E4: 0 | F4: 0 | G4: Brisé (-50% Armure) | H4: FALSE | L4: 1
G5: Choc magique (-50% Rés. Mag.) | H5: FALSE | L5: 0
A6: AD | B6: ='Stats Erwan'!G6 -> 125 | C6: 20 | D6: =B6+C6 -> 145 | E6: 145 | F6: 145 | G6: Anéanti (-50% Armure & Rés. Mag.) | H6: FALSE
A7: AP | B7: ='Stats Erwan'!G8 -> 105 | D7: =B7+C7 -> 105 | E7: 105 | F7: 105 | G7: Affaiblissement (-50% AD) | H7: FALSE
F8: 0 | G8: Érosion magique (-50% AP) | H8: FALSE
A9: Armure | B9: ='Stats Erwan'!G10 -> 26 | D9: =B9+C9 -> 26 | E9: 26 | F9: 26 | G9: Épuisement (-50% AD/AP) | H9: FALSE
A10: Rés. Mag. | B10: ='Stats Erwan'!G12 -> 21 | D10: =B10+C10 -> 21 | E10: 21 | F10: 21 | G10: Peau de fer (+50% Armure) | H10: FALSE | K10: 97 | L10: 92
G11: Esprit d'acier(+50% Rés. Mag. | H11: FALSE | K11: 172 | L11: 283
A12: % Critique | B12: ='Stats Erwan'!G14 -> 35 | C12: 10 | D12: =B12+C12 -> 45 | E12: 45 | F12: 45 | G12: Inflexible (+50% Armure & Rés. Mag.) | H12: FALSE
A13: % Dégâts critique | B13: ='Stats Erwan'!G16 -> 190 | D13: =B13+C13 -> 190 | E13: 190 | G13: Bravoure (+50% AD) | H13: FALSE
A14: Type de léthalité | B14: 0 = pas de léthalité | C14: 1=léthalité physique | D14: 2=léthalité magique | E14: 3=léthalité phys. et mag. | F14: 0 | G14: Foi (+50% AP) | H14: FALSE
A15: % Vol de vie | D15: =B15+C15 -> 0 | E15: 0 | G15: Héroïsme (+50% AP/AD) | H15: FALSE
A16: % Sapience | B16: ='Stats Erwan'!G18 -> 15 | D16: =B16+C16 -> 15 | E16: 15 | G16: Aiguisage (% Crit doublé) | H16: FALSE
A17: % Omnivamp | D17: =B17+C17 -> 0 | E17: 0
J22: Comp 2 (tours restants) | K22: TRUE
J23: Comp 2 durée fumigène | K23: 0
A26: Inventaire : | B26: Catégorie d'objet | C26: Nom d'objet | D26: Quantité | E26: Commentaires
B27: Équipement | C27: Dague (Loyauté) | D27: 2
B28: Équipement | C28: Épée* (NI) | D28: 1
B29: Consommables | C29: Potion soin mineur | D29: 1 | E29: Rend (15 + 15%) HP
B30: Consommables | C30: Potion mana mineur | D30: 1 | E30: Rend (10 + 10%) Mana
B31: Consommables | C31: Parchemins (NI) | D31: 2 | G31: pierre de talia
B32: Consommables | C32: Cristal explosif | D32: 1
B33: Consommables | C33: Cristal très explosif | D33: 1
B34: Butin | C34: butin de monstre tuto | D34: 1
B35: Butin | C35: Pièces de platine (pp) | D35: 0
B36: Butin | C36: Pièces d'or (Po) | D36: 10 | E36: 10 pièces d'or = 1 pièce de platine
B37: Butin | C37: Pièces d'argent (Pa) | D37: 10 | E37: 100 pièces d'argent = 1 pièce d'or
B38: Butin | C38: Pièces de cuivre (Pc | D38: 10 | E38: 100 pièces de cuivres = 1 pièce d'argent

Sheet Stats Bap
A1: Force | B1: Habileté | C1: Mental | D1: Magie/Cosmique | E1: Total Points | G1: HP | H1: HP (normal) | I1: HP (transcendant)
A2: 6 | B2: 1 | C2: 5 | D2: 0 | E2: =A2+B2+C2+D2 -> 12 | G2: =H2+I2 -> 685 | H2: =10 + CEILING(MIN(A2,16)*75 + MIN(D2,16)*5 + MIN(C2,16)*45, 1) -> 685 | I2: =CEILING(MAX(A2-16,0)^2*300 + MAX(D2-16,0)^2*25 + MAX(C2-16,0)^2*175,1) -> 0
A3: 20 AD | B3: 10 AD | C3: 5 AD | G3: Mana | H3: Mana (normal) | I3: Mana (transcendant)
B4: 10 AP | C4: 5 AP | D4: 20 AP | G4: =H4+I4 -> 180 | H4: =10 + CEILING(MIN(B2,16)*20 + MIN(D2,16)*75 + MIN(C2,16)*30, 1) -> 180 | I4: =CEILING(MAX(D2-16,0)^2*300 + MAX(B2-16,0)^2*80 + MAX(C2-16,0)^2*120,1) -> 0
A5: 75 HP | C5: 45 HP | D5: 5 HP | G5: AD | H5: AD (normal) | I5: AD (transcendant)
B6: 20 Mana | C6: 30 Mana | D6: 75 Mana | G6: =H6+I6 -> 155 | H6: =CEILING(MIN(A2,16)*20 + MIN(B2,16)*10 + MIN(C2,16)*5, 1) -> 155 | I6: =CEILING(MAX(A2-16,0)^2*172.5 + MAX(B2-16,0)^2*86.25 + MAX(C2-16,0)^2*28.75,1) -> 0
B7: 5% Crit | G7: AP | H7: AP (normal) | I7: AP (transcendant)
B8: 2-3% Sapience | G8: =H8+I8 -> 35 | H8: =CEILING(MIN(B2,16)*10 + MIN(D2,16)*20 + MIN(C2,16)*5, 1) -> 35 | I8: =CEILING(MAX(D2-16,0)^2*172.5 + MAX(B2-16,0)^2*86.25 + MAX(C2-16,0)^2*28.75,1) -> 0
A9: 2% D. Crit | B9: 5% D. Crit | D9: 2% D. Crit | G9: Armure | H9: Armure (normal) | I9: Armure (transcendant)
A10: 4-5 Armure | B10: 1 Armure | C10: 6 Armure | G10: =H10+I10 -> 58 | H10: =CEILING(MIN(A2,16)*4.5 + MIN(B2,16)*1 + MIN(C2,16)*6, 1) -> 58 | I10: =CEILING(MAX(A2-16,0)^2*14 + MAX(C2-16,0)^2*20 + MAX(B2-16,0)^2*2,1) -> 0
B11: 1 Rés. Mag. | C11: 6 Rés. Mag | D11: 4-5 Rés. Mag. | G11: Rés. Mag | H11: Rés. Mag (normal) | I11: Rés. Mag (transcendant)
G12: =H12+I12 -> 31 | H12: =CEILING(MIN(B2,16)*1 + MIN(D2,16)*4.5 + MIN(C2,16)*6, 1) -> 31 | I12: =CEILING(MAX(D2-16,0)^2*14 + MAX(C2-16,0)^2*20 + MAX(B2-16,0)^2*2,1) -> 0
A13: Niveau | B13: Points gagnés | C13: Total des points | D13: Limite stats | G13: % Crit | H13: % Crit (normal)
A14: 1 | B14: 10 (départ) | C14: 10 | D14: 5 | G14: =H14 -> 10 | H14: =5 + CEILING(MIN(B2,20)*5, 1) -> 10
A15: 2 | B15: 1 | C15: 11 | D15: 6 | G15: % D. Crit | H15: % D. Crit (normal) | I15: % D. Crit (transcendant)
A16: 3 | B16: 1 | C16: 12 | D16: 7 | G16: =H16+I16 -> 167 | H16: =150 + CEILING(MIN(A2,16)*2 + MIN(D2,16)*2 + MIN(B2,16)*5, 1) -> 167 | I16: =CEILING(MAX(A2-16,0)^2*(3+(1/3)) + MAX(D2-16,0)^2*(3+(1/3)) + MAX(B2-16,0)^2*(8+(1/3)),1) -> 0
A17: 4 | B17: 2 | C17: 14 | D17: 8 | G17: Sapience | H17: Sapience (normal) | I17: Sapience (transcendant)
A18: 5 | B18: 1 | C18: 15 | D18: 9 | G18: =H18 -> 3 | H18: =CEILING(MIN(B2,16)*2.5, 1) -> 3
A19: 6 | B19: 2 | C19: 17 | D19: 10
A20: 7 | B20: 1 | C20: 18 | D20: 11
A21: 8 | B21: 1 | C21: 19 | D21: 12
A22: 9 | B22: 2 | C22: 21 | D22: 13
A23: 10 | B23: 1 | C23: 22 | D23: 14
A24: 11 | B24: 1 | C24: 23 | D24: 15
A25: 12 | B25: 2 | C25: 25 | D25: 16
A26: 13 | B26: 1 | C26: 26 | D26: 16
A27: 14 | B27: 1 | C27: 27 | D27: 16
A28: 15 | B28: 2 | C28: 29 | D28: 16
A29: 16 | B29: 1 | C29: 30 | D29: 16
A30: 17 | B30: 1 | C30: 31 | D30: 16
A31: 18 | B31: 2 | C31: 33 | D31: 16

Sheet Grille Personnage
A1: Colonne 1 | B1: Valeurs stats | C1: Modificateurs | D1: Valeurs max | E1: Valeurs actuels | F1: Colonne 3 | G1: Buffs/Débuffs | H1: Colonne 2
A2: HP | B2: =Statistiques!G2 -> 6245 | D2: =B2+C2 -> 6245 | E2: 15 | G2: Miraculé (+50% Soins/Bouclier) | H2: FALSE
A3: Mana | B3: =Statistiques!G4 -> 350 | D3: =B3+C3 -> 350 | E3: 555 | G3: Hémorragie (-50% Soins/Bouclier) | H3: FALSE
A4: Bouclier | E4: 0 | G4: Brisé (-50% Armure) | H4: FALSE
G5: Choc magique (-50% Rés. Mag.) | H5: FALSE
A6: AD | B6: =Statistiques!G6 -> 3125 | D6: =B6+C6 -> 3125 | E6: 35 | G6: Anéanti (-50% Armure & Rés. Mag.) | H6: FALSE
A7: AP | B7: =Statistiques!G8 -> 85 | D7: =B7+C7 -> 85 | E7: 135 | G7: Affaiblissement (-50% AD) | H7: FALSE
G8: Érosion magique (-50% AP) | H8: FALSE
A9: Armure | B9: =Statistiques!G10 -> 328 | D9: =B9+C9 -> 328 | E9: 31 | G9: Épuisement (-50% AD/AP) | H9: FALSE
A10: Rés. Mag. | B10: =Statistiques!G12 -> 41 | D10: =B10+C10 -> 41 | E10: 54 | G10: Peau de fer (+50% Armure) | H10: FALSE
G11: Esprit d'acier(+50% Rés. Mag. | H11: FALSE
A12: % Critique | B12: =Statistiques!G14 -> 15 | D12: =B12+C12 -> 15 | E12: 10 | G12: Inflexible (+50% Armure & Rés. Mag.) | H12: FALSE
A13: % Dégâts critique | B13: =Statistiques!G16 -> 250 | D13: =B13+C13 -> 250 | E13: 165 | G13: Bravoure (+50% AD) | H13: FALSE
G14: Foi (+50% AP) | H14: FALSE
A15: % Vol de vie | D15: =B15+C15 -> 0 | E15: 0 | G15: Héroïsme (+50% AP/AD) | H15: FALSE
A16: % Sapience | B16: =Statistiques!G18 -> 5 | D16: =B16+C16 -> 5 | E16: 3 | G16: Aiguisage (% Crit doublé) | H16: FALSE
A17: % Omnivamp | D17: =B17+C17 -> 0 | E17: 0

Sheet Grille Baptiste
A1: Colonne 1 | B1: Valeurs stats | C1: Modificateurs | D1: Valeurs max | E1: Valeurs avant buff/débuff | F1: Valeurs effectives | G1: Buffs/Débuffs | H1: Colonne 2 | I1: Colonne 3 | K1: Maîtrise | L1: Catégorie d'arme | M1: Dégâts
A2: HP | B2: ='Stats Bap'!G2 -> 685 | C2: 50 | D2: =B2+C2 -> 735 | E2: 0 | F2: 0 | G2: Miraculé (+50% Soins/Bouclier) | H2: FALSE | K2: TRUE | L2: Gantelet renforcé | M2: 155 | N2: =M2*1.5 -> 232.5 | O2: =M2*1.75 -> 271.25
A3: Mana | B3: ='Stats Bap'!G4 -> 180 | D3: =B3+C3 -> 180 | E3: 40 | F3: 40 | G3: Hémorragie (-50% Soins/Bouclier) | H3: FALSE | K3: Physique | L3: 1H | M3: 310
A4: Bouclier | E4: 0 | F4: 0 | G4: Brisé (-50% Armure) | H4: FALSE | L4: 1
G5: Choc magique (-50% Rés. Mag.) | H5: FALSE
A6: AD | B6: ='Stats Bap'!G6 -> 155 | D6: =B6+C6 -> 155 | E6: 155 | F6: 155 | G6: Anéanti (-50% Armure & Rés. Mag.) | H6: FALSE | K6: Mouvement Bonus
A7: AP | B7: ='Stats Bap'!G8 -> 35 | D7: =B7+C7 -> 35 | E7: 35 | F7: 35 | G7: Affaiblissement (-50% AD) | H7: FALSE | K7: 3
G8: Érosion magique (-50% AP) | H8: FALSE
A9: Armure | B9: ='Stats Bap'!G10 -> 58 | D9: =B9+C9 -> 58 | E9: 58 | F9: 58 | G9: Épuisement (-50% AD/AP) | H9: FALSE
A10: Rés. Mag. | B10: ='Stats Bap'!G12 -> 31 | D10: =B10+C10 -> 31 | E10: 31 | F10: 31 | G10: Peau de fer (+50% Armure) | H10: FALSE | R10: 310
G11: Esprit d'acier(+50% Rés. Mag. | H11: FALSE
A12: % Critique | B12: ='Stats Bap'!G14 -> 10 | D12: =B12+C12 -> 10 | E12: 10 | F12: 10 | G12: Inflexible (+50% Armure & Rés. Mag.) | H12: FALSE
A13: % Dégâts critique | B13: ='Stats Bap'!G16 -> 167 | D13: =B13+C13 -> 167 | E13: 167 | G13: Bravoure (+50% AD) | H13: FALSE | O13: 34
A14: Type de léthalité | B14: 0 = pas de léthalité | C14: 1=léthalité physique | D14: 2=léthalité magique | E14: 3=léthalité phys. et mag. | F14: 0 | G14: Foi (+50% AP) | H14: FALSE
A15: % Vol de vie | D15: =B15+C15 -> 0 | E15: 0 | G15: Héroïsme (+50% AP/AD) | H15: FALSE | L15: menaces : territoire un peu sécu, docu de noxus, pas forcément à jour
A16: % Sapience | D16: =B16+C16 -> 0 | E16: 0 | G16: Aiguisage (% Crit doublé) | H16: FALSE | L16: parmis les biomes : att en quittant le champs des dunes (désert classique). Biomes suivants bcp moins recommandé !
A17: % Omnivamp | C17: 10 | D17: =B17+C17 -> 10 | E17: 10 | L17: BRAS DROIT OUT
G19: État de Fatigue : 2
G20: STOCKS : 2
H21: distance : 7 cases
H22: 9 cases
A23: Inventaire : | B23: Catégorie d'objet | C23: Nom d'objet | D23: Quantité | E23: Commentaires
B24: Équipement | C24: gantelet | D24: 1
B26: Consommables | C26: Potion soin mineur | D26: 1 | E26: Rend (15 + 15%) HP
B27: Consommables | C27: Potion mana mineur | D27: 1 | E27: Rend (10 + 10%) Mana
B28: Butin | C28: Pièces de platine (pp) | D28: 0
B29: Butin | C29: Pièces d'or (Po) | D29: 10 | E29: 10 pièces d'or = 1 pièce de platine
B30: Butin | C30: Pièces d'argent (Pa) | D30: 10 | E30: 100 pièces d'argent = 1 pièce d'or
B31: Butin | C31: Pièces de cuivre (Pc | D31: 10 | E31: 100 pièces de cuivres = 1 pièce d'argent
B37: OBJET | C37: KEMINITE | D37: 1 | E37: APPEL TALIYAH
G38: Urskaar
G39: ?
G40: Jett
G41: Élias
G42: Smith
G43: Rathael

Sheet Journal
A1: Date | B1: Arme | C1: Type | D1: Mode | E1: Critique | F1: Dégâts
A2: 45752.662 | B2: Lance | C2: Physique | D2: offensif | E2: Non | F2: 131
A3: 45752.664 | B3: Lance | C3: Physique | D3: défensif | E3: Non | F3: 0
A4: 45752.804 | B4: Lance | C4: Physique | D4: offensif | E4: Non | F4: 43
A5: 45752.805 | B5: Lance | C5: Physique | D5: defensif | E5: Non | F5: 0
A6: 45752.805 | B6: Lance | C6: Physique | D6: offensif | E6: Non | F6: 43
A7: 45752.805 | B7: Lance | C7: Physique | D7: offensif | E7: Non | F7: 43
A8: 45752.822 | B8: Dague | C8: Physique | D8: offensif | E8: Non | F8: 131
A9: 45752.823 | B9: Lance | C9: Physique | D9: équilibré | E9: Oui | F9: 318
A10: 45752.823 | B10: Dague | C10: Physique | D10: équilibré | E10: Non | F10: 105
A11: 45752.823 | B11: Dague | C11: Physique | D11: défensif | E11: Non | F11: 0
A12: 45752.835 | B12: Dague | C12: Physique | D12: offensif | E12: Non | F12: 131
A13: 45752.835 | B13: Dague | C13: Physique | D13: offensif | E13: Non | F13: 131
... A107: 45843.783 | B107: Dague | C107: Physique | D107: offensif | E107: Oui | F107: 236
A108: 46061.547 | B108: Grille JB | C108: Dague | D108: Non | E108: Physique | F108: 1H | G108: 1 | H108: Aucune (non maîtrisée) | I108: Oui | J108: 97
A109: 46061.547 | B109: Grille JB | C109: Dague | D109: Oui | E109: Physique | F109: 1H | G109: 1 | H109: Fourberie, Mini-Arme | I109: Non | J109: 130
A110: 46061.55 | B110: Grille Fab | C110: Arc long | D110: Non | E110: Physique | F110: 2H | G110: 10 | H110: Aucune (non maîtrisée) | I110: Non | J110: 0
A111: 46061.55 | B111: Grille Fab | C111: Arc long | D111: Non | E111: Physique | F111: 2H | G111: 10 | H111: Aucune (non maîtrisée) | I111: Non | J111: 0
A112: 46061.551 | B112: Grille Fab | C112: Arc long | D112: Non | E112: Physique | F112: 2H | G112: 10 | H112: Aucune (non maîtrisée) | I112: Non | J112: 0
A113: 46061.555 | B113: Grille Steph | C113: Dague | D113: Non | E113: Physique | F113: 1H | G113: 1 | H113: Aucune (non maîtrisée) | I113: Non | J113: 0
A114: 46061.556 | B114: Grille Steph | C114: Dague | D114: Non | E114: Physique | F114: 1H | G114: 1 | H114: Aucune (non maîtrisée) | I114: Non | J114: 0
A115: 46061.557 | B115: Grille Steph | C115: Masse d’armes | D115: Non | E115: Physique | F115: 1H | G115: 1 | H115: Aucune (non maîtrisée) | I115: Non | J115: 56
A116: 46061.558 | B116: Grille Steph | C116: Masse d’armes | D116: Oui | E116: Physique | F116: 1H | G116: 1 | H116: Assommage, Focalisation, Mini-Arme | I116: Oui | J116: 75
A117: 46061.558 | B117: Grille Steph | C117: Masse d’armes | D117: Oui | E117: Physique | F117: 1H | G117: 1 | H117: Focalisation (+Mana) | I117: Non | J117: 0
A118: 46061.564 | B118: Grille Erwan | C118: Dague | D118: Non | E118: Physique | F118: 1H | G118: 1 | H118: Aucune (non maîtrisée) | I118: Non | J118: 78
A119: 46061.573 | B119: Grille Erwan | C119: Dague | D119: Non | E119: Physique | F119: 1H | G119: 1 | H119: Aucune (non maîtrisée) | I119: Oui | J119: 78
... A156: 46061.731 | B156: Grille Fab | C156: Relique lunaire/solaire | D156: Oui | E156: Magique | F156: 2H | G156: 6 | H156: Connexion astrale | I156: Oui | J156: 200
A157: 46088.463 | B157: Grille Baptiste | C157: Comp1 Pugilat (Gauche) | D157: Pas d'attaque d'opportunité ce tour | E157: Non | F157: 145 | G157: Coût mana: 30
A158: 46088.464 | B158: Grille Baptiste | C158: Comp1 Pugilat (Gauche) | D158: Pas d'attaque d'opportunité ce tour | E158: Non | F158: 145 | G158: Coût mana: 30
A159: 46088.478 | B159: Grille Baptiste | C159: Gantelet renforcé | D159: Oui | E159: Physique | F159: 1H | G159: 1 | H159: Voie de l’ours : +150% | I159: Non | J159: 362
A160: 46088.478 | B160: Grille Baptiste | C160: Gantelet renforcé | D160: Oui | E160: Physique | F160: 1H | G160: 1 | H160: Combo | I160: Oui | J160: 145
A161: 46088.479 | B161: Grille Baptiste | C161: Gantelet renforcé | D161: Oui | E161: Physique | F161: 1H | G161: 1 | H161: Combo | I161: Non | J161: 145
A162: 46088.484 | B162: Grille Baptiste | C162: Gantelet renforcé | D162: Oui | E162: Physique | F162: 1H | G162: 1 | H162: Voie de l’ours : +175% | I162: Non | J162: 398
A163: 46088.488 | B163: Grille Baptiste | C163: Gantelet renforcé | D163: Oui | E163: Physique | F163: 1H | G163: 1 | H163: Voie de l’ours : +175% | I163: Oui | J163: 253
A164: 46088.531 | B164: Grille Baptiste | C164: Comp1 Pugilat (Droite) | D164: #ERROR! | E164: Non | F164: 217 | G164: Coût mana: 30
A165: 46088.564 | B165: Grille Baptiste | C165: Gantelet renforcé | D165: Oui | E165: Physique | F165: 1H | G165: 1 | H165: Voie de l’ours : +150% | I165: Non | J165: 217
A166: 46088.569 | B166: Grille Baptiste | C166: Gantelet renforcé | D166: Oui | E166: Physique | F166: 1H | G166: 1 | H166: Voie de l’ours : +150% | I166: Oui | J166: 217
A167: 46088.572 | B167: Grille Baptiste | C167: Gantelet renforcé | D167: Oui | E167: Physique | F167: 1H | G167: 1 | H167: Combo | I167: Non | J167: 145
A168: 46088.572 | B168: Grille Baptiste | C168: Gantelet renforcé | D168: Oui | E168: Physique | F168: 1H | G168: 1 | H168: Voie de l’ours : +175% | I168: Oui | J168: 253
A169: 46090.953 | B169: Grille Fab | C169: Relique lunaire/solaire | D169: Oui | E169: Magique | F169: 2H | G169: 6 | H169: Connexion astrale | I169: Oui | J169: 190
...

Sheet Stats JB
A1: Force | B1: Habileté | C1: Mental | D1: Magie/Cosmique | E1: Total Points | G1: HP | H1: HP (normal) | I1: HP (transcendant)
A2: 4 | B2: 3 | C2: 4 | D2: 1 | E2: =SUM(A2:D2) -> 12 | G2: =H2+I2 -> 495 | H2: =10 + CEILING(MIN(A2,16)*75 + MIN(D2,16)*5 + MIN(C2,16)*45, 1) -> 495 | I2: =CEILING(MAX(A2-16,0)^2*300 + MAX(D2-16,0)^2*25 + MAX(C2-16,0)^2*175,1) -> 0
A3: 20 AD | B3: 10 AD | C3: 5 AD | G3: Mana | H3: Mana (normal) | I3: Mana (transcendant)
B4: 10 AP | C4: 5 AP | D4: 20 AP | G4: =H4+I4 -> 265 | H4: =10 + CEILING(MIN(B2,16)*20 + MIN(D2,16)*75 + MIN(C2,16)*30, 1) -> 265 | I4: =CEILING(MAX(D2-16,0)^2*300 + MAX(B2-16,0)^2*80 + MAX(C2-16,0)^2*120,1) -> 0
A5: 75 HP | C5: 45 HP | D5: 5 HP | G5: AD | H5: AD (normal) | I5: AD (transcendant)
B6: 20 Mana | C6: 30 Mana | D6: 75 Mana | G6: =H6+I6 -> 130 | H6: =CEILING(MIN(A2,16)*20 + MIN(B2,16)*10 + MIN(C2,16)*5, 1) -> 130 | I6: =CEILING(MAX(A2-16,0)^2*172.5 + MAX(B2-16,0)^2*86.25 + MAX(C2-16,0)^2*28.75,1) -> 0
B7: 5% Crit | G7: AP | H7: AP (normal) | I7: AP (transcendant)
B8: 2-3% Sapience | G8: =H8+I8 -> 70 | H8: =CEILING(MIN(B2,16)*10 + MIN(D2,16)*20 + MIN(C2,16)*5, 1) -> 70 | I8: =CEILING(MAX(D2-16,0)^2*172.5 + MAX(B2-16,0)^2*86.25 + MAX(C2-16,0)^2*28.75,1) -> 0
A9: 2% D. Crit | B9: 5% D. Crit | D9: 2% D. Crit | G9: Armure | H9: Armure (normal) | I9: Armure (transcendant)
A10: 4-5 Armure | B10: 1 Armure | C10: 6 Armure | G10: =H10+I10 -> 45 | H10: =CEILING(MIN(A2,16)*4.5 + MIN(B2,16)*1 + MIN(C2,16)*6, 1) -> 45 | I10: =CEILING(MAX(A2-16,0)^2*14 + MAX(C2-16,0)^2*20 + MAX(B2-16,0)^2*2,1) -> 0
B11: 1 Rés. Mag. | C11: 6 Rés. Mag | D11: 4-5 Rés. Mag. | G11: Rés. Mag | H11: Rés. Mag (normal) | I11: Rés. Mag (transcendant)
G12: =H12+I12 -> 32 | H12: =CEILING(MIN(B2,16)*1 + MIN(D2,16)*4.5 + MIN(C2,16)*6, 1) -> 32 | I12: =CEILING(MAX(D2-16,0)^2*14 + MAX(C2-16,0)^2*20 + MAX(B2-16,0)^2*2,1) -> 0
A13: Niveau | B13: Points gagnés | C13: Total des points | D13: Limite stats | G13: % Crit | H13: % Crit (normal)
A14: 1 | B14: 10 (départ) | C14: 10 | D14: 5 | G14: =H14 -> 20 | H14: =5 + CEILING(MIN(B2,20)*5, 1) -> 20
A15: 2 | B15: 1 | C15: 11 | D15: 6 | G15: % D. Crit | H15: % D. Crit (normal) | I15: % D. Crit (transcendant)
A16: 3 | B16: 1 | C16: 12 | D16: 7 | G16: =H16+I16 -> 175 | H16: =150 + CEILING(MIN(A2,16)*2 + MIN(D2,16)*2 + MIN(B2,16)*5, 1) -> 175 | I16: =CEILING(MAX(A2-16,0)^2*(3+(1/3)) + MAX(D2-16,0)^2*(3+(1/3)) + MAX(B2-16,0)^2*(8+(1/3)),1) -> 0
A17: 4 | B17: 2 | C17: 14 | D17: 8 | G17: Sapience | H17: Sapience (normal) | I17: Sapience (transcendant)
A18: 5 | B18: 1 | C18: 15 | D18: 9 | G18: =H18 -> 8 | H18: =CEILING(MIN(B2,16)*2.5, 1) -> 8
A19: 6 | B19: 2 | C19: 17 | D19: 10
A20: 7 | B20: 1 | C20: 18 | D20: 11
A21: 8 | B21: 1 | C21: 19 | D21: 12
A22: 9 | B22: 2 | C22: 21 | D22: 13
A23: 10 | B23: 1 | C23: 22 | D23: 14
A24: 11 | B24: 1 | C24: 23 | D24: 15
A25: 12 | B25: 2 | C25: 25 | D25: 16
A26: 13 | B26: 1 | C26: 26 | D26: 16
A27: 14 | B27: 1 | C27: 27 | D27: 16 | G27: çalu çalu
A28: 15 | B28: 2 | C28: 29 | D28: 16
A29: 16 | B29: 1 | C29: 30 | D29: 16
A30: 17 | B30: 1 | C30: 31 | D30: 16
A31: 18 | B31: 2 | C31: 33 | D31: 16

Sheet Grille JB
A1: Colonne 1 | B1: Valeurs stats | C1: Modificateurs | D1: Valeurs max | E1: Valeurs avant buff/débuff | F1: Valeurs effectives | G1: Buffs/Débuffs | H1: Colonne 2 | K1: Maîtrise | L1: Catégorie d'arme | M1: Dégâts
A2: HP | B2: ='Stats JB'!G2 -> 495 | D2: =B2+C2 -> 495 | E2: 0 | F2: 0 | G2: Miraculé (+50% Soins/Bouclier) | H2: FALSE | K2: TRUE | L2: Claymore | M2: 315 | O2: Rune Domination/ Sadisme
A3: Mana | B3: ='Stats JB'!G4 -> 265 | D3: =B3+C3 -> 265 | E3: 235 | F3: 235 | G3: Hémorragie (-50% Soins/Bouclier) | H3: FALSE | K3: Physique | L3: 2H | O3: 10 Letalité
A4: Bouclier | E4: 0 | F4: 0 | G4: Brisé (-50% Armure) | H4: FALSE | L4: 2
G5: Choc magique (-50% Rés. Mag.) | H5: FALSE
A6: AD | B6: ='Stats JB'!G6 -> 130 | C6: 20 | D6: =B6+C6 -> 150 | E6: 150 | F6: 150 | G6: Anéanti (-50% Armure & Rés. Mag.) | H6: FALSE
A7: AP | B7: =Statistiques!G8 -> 85 | D7: =B7+C7 -> 85 | E7: 85 | F7: 85 | G7: Affaiblissement (-50% AD) | H7: FALSE
G8: Érosion magique (-50% AP) | H8: FALSE
A9: Armure | B9: ='Stats JB'!G10 -> 45 | D9: =B9+C9 -> 45 | E9: 56 | F9: 56 | G9: Épuisement (-50% AD/AP) | H9: FALSE
A10: Rés. Mag. | B10: ='Stats JB'!G12 -> 32 | D10: =B10+C10 -> 32 | E10: 40 | F10: 40 | G10: Peau de fer (+50% Armure) | H10: FALSE
G11: Esprit d'acier(+50% Rés. Mag. | H11: FALSE | J11: Glaciation | K11: 5 | L11: 0
A12: % Critique | B12: ='Stats JB'!G14 -> 20 | D12: =B12+C12 -> 20 | E12: 20 | F12: 20 | G12: Inflexible (+50% Armure & Rés. Mag.) | H12: FALSE | J12: Compteur de dégâts (max par tour) | K12: 2
A13: % Dégâts critique | B13: =Statistiques!G16 -> 250 | D13: =B13+C13 -> 250 | E13: 210 | G13: Bravoure (+50% AD) | H13: FALSE | J13: Ame fendue | K13: TRUE
A14: Type de léthalité | B14: 0 = pas de léthalité | C14: 1=léthalité physique | D14: 2=léthalité magique | E14: 3=léthalité phys. et mag. | F14: 0 | G14: Foi (+50% AP) | H14: FALSE | J14: Compteur de tour (mur de givre) | K14: 0 | M14: Static, augmente les resistances + petit shield
A15: % Vol de vie | D15: =B15+C15 -> 0 | E15: 0 | G15: Héroïsme (+50% AP/AD) | H15: FALSE | J15: Mur de givre (activé ou non) | K15: FALSE
A16: % Sapience | B16: ='Stats JB'!G18 -> 8 | D16: =B16+C16 -> 8 | E16: 8 | G16: Aiguisage (% Crit doublé) | H16: FALSE
A17: % Omnivamp | D17: =B17+C17 -> 0 | E17: 0 | K17: Claymore Bouclier Hache
I20: Fatigue : 1
I21: Eau : 3
A23: Inventaire : | B23: Catégorie d'objet | C23: Nom d'objet | D23: Quantité | E23: Commentaires
B24: Équipement | C24: Claymore | D24: 1 | E24: 10 AD (jusqu'à la fin de la traversée))
B25: Équipement | C25: Épée + Bouclier | D25: 1
B26: Consommables | C26: Potion soin mineur | D26: 0 | E26: Rend (15 + 15%) HP
B27: Consommables | C27: Potion mana mineur | D27: 1 | E27: Rend (10 + 10%) Mana
B28: Butin | C28: Pièces de platine (pp) | D28: 0
B29: Butin | C29: Pièces d'or (Po) | D29: 10 | E29: 10 pièces d'or = 1 pièce de platine
B30: Butin | C30: Pièces d'argent (Pa) | D30: 10 | E30: 100 pièces d'argent = 1 pièce d'or
B31: Butin | C31: Pièces de cuivre (Pc | D31: 10 | E31: 100 pièces de cuivres = 1 pièce d'argent
B32: Butin | C32: Kéminite | D32: 1 | E32: Sert a appeler Taliyah

Sheet Stats Steph
A1: Force | B1: Habileté | C1: Mental | D1: Magie/Cosmique | E1: Total Points | G1: HP | H1: HP (normal) | I1: HP (transcendant)
A2: 1 | B2: 6 | C2: 1 | D2: 4 | E2: =SUM(A2:D2) -> 12 | G2: =H2+I2 -> 150 | H2: =10 + CEILING(MIN(A2,16)*75 + MIN(D2,16)*5 + MIN(C2,16)*45, 1) -> 150 | I2: =CEILING(MAX(A2-16,0)^2*300 + MAX(D2-16,0)^2*25 + MAX(C2-16,0)^2*175,1) -> 0
A3: 20 AD | B3: 10 AD | C3: 5 AD | G3: Mana | H3: Mana (normal) | I3: Mana (transcendant)
B4: 10 AP | C4: 5 AP | D4: 20 AP | G4: =H4+I4 -> 460 | H4: =10 + CEILING(MIN(B2,16)*20 + MIN(D2,16)*75 + MIN(C2,16)*30, 1) -> 460 | I4: =CEILING(MAX(D2-16,0)^2*300 + MAX(B2-16,0)^2*80 + MAX(C2-16,0)^2*120,1) -> 0
A5: 75 HP | C5: 45 HP | D5: 5 HP | G5: AD | H5: AD (normal) | I5: AD (transcendant)
B6: 20 Mana | C6: 30 Mana | D6: 75 Mana | G6: =H6+I6 -> 85 | H6: =CEILING(MIN(A2,16)*20 + MIN(B2,16)*10 + MIN(C2,16)*5, 1) -> 85 | I6: =CEILING(MAX(A2-16,0)^2*172.5 + MAX(B2-16,0)^2*86.25 + MAX(C2-16,0)^2*28.75,1) -> 0
B7: 5% Crit | G7: AP | H7: AP (normal) | I7: AP (transcendant)
B8: 2-3% Sapience | G8: =H8+I8 -> 145 | H8: =CEILING(MIN(B2,16)*10 + MIN(D2,16)*20 + MIN(C2,16)*5, 1) -> 145 | I8: =CEILING(MAX(D2-16,0)^2*172.5 + MAX(B2-16,0)^2*86.25 + MAX(C2-16,0)^2*28.75,1) -> 0
A9: 2% D. Crit | B9: 5% D. Crit | D9: 2% D. Crit | G9: Armure | H9: Armure (normal) | I9: Armure (transcendant)
A10: 4-5 Armure | B10: 1 Armure | C10: 6 Armure | G10: =H10+I10 -> 17 | H10: =CEILING(MIN(A2,16)*4.5 + MIN(B2,16)*1 + MIN(C2,16)*6, 1) -> 17 | I10: =CEILING(MAX(A2-16,0)^2*14 + MAX(C2-16,0)^2*20 + MAX(B2-16,0)^2*2,1) -> 0
B11: 1 Rés. Mag. | C11: 6 Rés. Mag | D11: 4-5 Rés. Mag. | G11: Rés. Mag | H11: Rés. Mag (normal) | I11: Rés. Mag (transcendant)
G12: =H12+I12 -> 30 | H12: =CEILING(MIN(B2,16)*1 + MIN(D2,16)*4.5 + MIN(C2,16)*6, 1) -> 30 | I12: =CEILING(MAX(D2-16,0)^2*14 + MAX(C2-16,0)^2*20 + MAX(B2-16,0)^2*2,1) -> 0
A13: Niveau | B13: Points gagnés | C13: Total des points | D13: Limite stats | G13: % Crit | H13: % Crit (normal)
A14: 1 | B14: 10 (départ) | C14: 10 | D14: 5 | G14: =H14 -> 35 | H14: =5 + CEILING(MIN(B2,20)*5, 1) -> 35
A15: 2 | B15: 1 | C15: 11 | D15: 6 | G15: % D. Crit | H15: % D. Crit (normal) | I15: % D. Crit (transcendant)
A16: 3 | B16: 1 | C16: 12 | D16: 7 | G16: =H16+I16 -> 190 | H16: =150 + CEILING(MIN(A2,16)*2 + MIN(D2,16)*2 + MIN(B2,16)*5, 1) -> 190 | I16: =CEILING(MAX(A2-16,0)^2*(3+(1/3)) + MAX(D2-16,0)^2*(3+(1/3)) + MAX(B2-16,0)^2*(8+(1/3)),1) -> 0
A17: 4 | B17: 2 | C17: 14 | D17: 8 | G17: Sapience | H17: Sapience (normal) | I17: Sapience (transcendant)
A18: 5 | B18: 1 | C18: 15 | D18: 9 | G18: =H18 -> 15 | H18: =CEILING(MIN(B2,16)*2.5, 1) -> 15
A19: 6 | B19: 2 | C19: 17 | D19: 10
A20: 7 | B20: 1 | C20: 18 | D20: 11
A21: 8 | B21: 1 | C21: 19 | D21: 12
A22: 9 | B22: 2 | C22: 21 | D22: 13
A23: 10 | B23: 1 | C23: 22 | D23: 14
A24: 11 | B24: 1 | C24: 23 | D24: 15
A25: 12 | B25: 2 | C25: 25 | D25: 16
A26: 13 | B26: 1 | C26: 26 | D26: 16
A27: 14 | B27: 1 | C27: 27 | D27: 16
A28: 15 | B28: 2 | C28: 29 | D28: 16
A29: 16 | B29: 1 | C29: 30 | D29: 16
A30: 17 | B30: 1 | C30: 31 | D30: 16
A31: 18 | B31: 2 | C31: 33 | D31: 16

Sheet Grille Steph
A1: Colonne 1 | B1: Valeurs stats | C1: Modificateurs | D1: Valeurs max | E1: Valeurs avant buff/débuff | F1: Valeurs effectives | G1: Buffs/Débuffs | H1: Colonne 2 | K1: Maîtrise | L1: Catégorie d'arme | M1: Dégâts
A2: HP | B2: ='Stats Steph'!G2 -> 150 | D2: =B2+C2 -> 150 | E2: 150 | F2: 150 | G2: Miraculé (+50% Soins/Bouclier) | H2: FALSE | K2: TRUE | L2: Épée courte | M2: 87
A3: Mana | B3: ='Stats Steph'!G4 -> 460 | D3: =B3+C3 -> 460 | E3: 345 | F3: 345 | G3: Hémorragie (-50% Soins/Bouclier) | H3: FALSE | K3: Physique | L3: Poly
A4: Bouclier | E4: 0 | F4: 0 | G4: Brisé (-50% Armure) | H4: FALSE | K4: 2 | L4: 1
G5: Choc magique (-50% Rés. Mag.) | H5: FALSE | K5: Flash | M5: potion : 15 (flat) + 15%
A6: AD | B6: ='Stats Steph'!G6 -> 85 | D6: =B6+C6 -> 85 | E6: 75 | F6: 75 | G6: Anéanti (-50% Armure & Rés. Mag.) | H6: FALSE | J6: Cellules déployées | K6: 3
A7: AP | B7: ='Stats Steph'!G8 -> 145 | D7: =B7+C7 -> 145 | E7: 145 | F7: 145 | G7: Affaiblissement (-50% AD) | H7: FALSE
G8: Érosion magique (-50% AP) | H8: FALSE
A9: Armure | B9: ='Stats Steph'!G10 -> 17 | D9: =B9+C9 -> 17 | E9: 17 | F9: 17 | G9: Épuisement (-50% AD/AP) | H9: FALSE
A10: Rés. Mag. | B10: ='Stats Steph'!G12 -> 30 | D10: =B10+C10 -> 30 | E10: 30 | F10: 30 | G10: Peau de fer (+50% Armure) | H10: FALSE
G11: Esprit d'acier(+50% Rés. Mag. | H11: FALSE
A12: % Critique | B12: ='Stats Steph'!G14 -> 35 | D12: =B12+C12 -> 35 | E12: 35 | F12: 35 | G12: Inflexible (+50% Armure & Rés. Mag.) | H12: FALSE
A13: % Dégâts critique | B13: ='Stats Steph'!G16 -> 190 | D13: =B13+C13 -> 190 | E13: 190 | G13: Bravoure (+50% AD) | H13: FALSE
A14: Type de léthalité | B14: 0 = pas de léthalité | C14: 1=léthalité physique | D14: 2=léthalité magique | E14: 3=léthalité phys. et mag. | F14: 0 | G14: Foi (+50% AP) | H14: FALSE
A15: % Vol de vie | D15: =B15+C15 -> 0 | E15: 0 | G15: Héroïsme (+50% AP/AD) | H15: FALSE
A16: % Sapience | B16: ='Stats Steph'!G18 -> 15 | D16: =B16+C16 -> 15 | E16: 15 | G16: Aiguisage (% Crit doublé) | H16: FALSE
A17: % Omnivamp | D17: =B17+C17 -> 0 | E17: 0
A24: Inventaire : | B24: Catégorie d'objet | C24: Nom d'objet | D24: Quantité | E24: Commentaires
B25: Équipement | C25: Arc hextech | D25: 1
B26: Équipement | C26: Dague | D26: 1
B27: Consommables | C27: Potion soin mineur | D27: 0 | E27: Rend (15 + 15%) HP
B28: Consommables | C28: Potion mana mineur | D28: 1 | E28: Rend (10 + 10%) Mana
B29: Butin | C29: Pièces de platine (pp) | D29: 0
B30: Butin | C30: 10 pièces d'or | D30: 1 | E30: 10 pièces d'or = 1 pièce de platine
B31: Butin | C31: 10 pièces d'argent | D31: 1 | E31: 100 pièces d'argent = 1 pièce d'or
B32: Butin | C32: 10 pièces de cuivre | D32: 1 | E32: 100 pièces de cuivres = 1 pièce d'argent
B33: Équipement | C33: Livre : L'Histoire de Runeterra | D33: 1
B34: Équipement | C34: Boite à outils | D34: 1
B35: Consommables | C35: Potion néfaste inconnu | D35: 2
B36: Consommables | C36: Pierre magique de transmutation | D36: 1

Sheet Stats Fab
A1: Force | B1: Habileté | C1: Mental | D1: Magie/Cosmique | E1: Total Points | G1: HP | H1: HP (normal) | I1: HP (transcendant)
A2: 5 | B2: 4 | C2: 3 | D2: 0 | E2: =SUM(A2:D2) -> 12 | G2: =H2+I2 -> 520 | H2: =10 + CEILING(MIN(A2,16)*75 + MIN(D2,16)*5 + MIN(C2,16)*45, 1) -> 520 | I2: =CEILING(MAX(A2-16,0)^2*300 + MAX(D2-16,0)^2*25 + MAX(C2-16,0)^2*175,1) -> 0
A3: 20 AD | B3: 10 AD | C3: 5 AD | G3: Mana | H3: Mana (normal) | I3: Mana (transcendant)
B4: 10 AP | C4: 5 AP | D4: 20 AP | G4: =H4+I4 -> 180 | H4: =10 + CEILING(MIN(B2,16)*20 + MIN(D2,16)*75 + MIN(C2,16)*30, 1) -> 180 | I4: =CEILING(MAX(D2-16,0)^2*300 + MAX(B2-16,0)^2*80 + MAX(C2-16,0)^2*120,1) -> 0
A5: 75 HP | C5: 45 HP | D5: 5 HP | G5: AD | H5: AD (normal) | I5: AD (transcendant)
B6: 20 Mana | C6: 30 Mana | D6: 75 Mana | E6: Fatigue | F6: 0 | G6: =H6+I6 -> 155 | H6: =CEILING(MIN(A2,16)*20 + MIN(B2,16)*10 + MIN(C2,16)*5, 1) -> 155 | I6: =CEILING(MAX(A2-16,0)^2*172.5 + MAX(B2-16,0)^2*86.25 + MAX(C2-16,0)^2*28.75,1) -> 0
B7: 5% Crit | E7: Eau | F7: 0 | G7: AP | H7: AP (normal) | I7: AP (transcendant)
B8: 2-3% Sapience | G8: =H8+I8 -> 55 | H8: =CEILING(MIN(B2,16)*10 + MIN(D2,16)*20 + MIN(C2,16)*5, 1) -> 55 | I8: =CEILING(MAX(D2-16,0)^2*172.5 + MAX(B2-16,0)^2*86.25 + MAX(C2-16,0)^2*28.75,1) -> 0
A9: 2% D. Crit | B9: 5% D. Crit | D9: 2% D. Crit | G9: Armure | H9: Armure (normal) | I9: Armure (transcendant)
A10: 4-5 Armure | B10: 1 Armure | C10: 6 Armure | G10: =H10+I10 -> 45 | H10: =CEILING(MIN(A2,16)*4.5 + MIN(B2,16)*1 + MIN(C2,16)*6, 1) -> 45 | I10: =CEILING(MAX(A2-16,0)^2*14 + MAX(C2-16,0)^2*20 + MAX(B2-16,0)^2*2,1) -> 0
B11: 1 Rés. Mag. | C11: 6 Rés. Mag | D11: 4-5 Rés. Mag. | G11: Rés. Mag | H11: Rés. Mag (normal) | I11: Rés. Mag (transcendant)
G12: =H12+I12 -> 22 | H12: =CEILING(MIN(B2,16)*1 + MIN(D2,16)*4.5 + MIN(C2,16)*6, 1) -> 22 | I12: =CEILING(MAX(D2-16,0)^2*14 + MAX(C2-16,0)^2*20 + MAX(B2-16,0)^2*2,1) -> 0
A13: Niveau | B13: Points gagnés | C13: Total des points | D13: Limite stats | G13: % Crit | H13: % Crit (normal)
A14: 1 | B14: 10 (départ) | C14: 10 | D14: 5 | G14: =H14 -> 25 | H14: =5 + CEILING(MIN(B2,20)*5, 1) -> 25
A15: 2 | B15: 1 | C15: 11 | D15: 6 | G15: % D. Crit | H15: % D. Crit (normal) | I15: % D. Crit (transcendant)
A16: 3 | B16: 1 | C16: 12 | D16: 7 | G16: =H16+I16 -> 180 | H16: =150 + CEILING(MIN(A2,16)*2 + MIN(D2,16)*2 + MIN(B2,16)*5, 1) -> 180 | I16: =CEILING(MAX(A2-16,0)^2*(3+(1/3)) + MAX(D2-16,0)^2*(3+(1/3)) + MAX(B2-16,0)^2*(8+(1/3)),1) -> 0
A17: 4 | B17: 2 | C17: 14 | D17: 8 | G17: Sapience | H17: Sapience (normal) | I17: Sapience (transcendant)
A18: 5 | B18: 1 | C18: 15 | D18: 9 | G18: =H18 -> 10 | H18: =CEILING(MIN(B2,16)*2.5, 1) -> 10
A19: 6 | B19: 2 | C19: 17 | D19: 10
A20: 7 | B20: 1 | C20: 18 | D20: 11
A21: 8 | B21: 1 | C21: 19 | D21: 12
A22: 9 | B22: 2 | C22: 21 | D22: 13
A23: 10 | B23: 1 | C23: 22 | D23: 14
A24: 11 | B24: 1 | C24: 23 | D24: 15
A25: 12 | B25: 2 | C25: 25 | D25: 16
A26: 13 | B26: 1 | C26: 26 | D26: 16
A27: 14 | B27: 1 | C27: 27 | D27: 16
A28: 15 | B28: 2 | C28: 29 | D28: 16
A29: 16 | B29: 1 | C29: 30 | D29: 16
A30: 17 | B30: 1 | C30: 31 | D30: 16
A31: 18 | B31: 2 | C31: 33 | D31: 16

Sheet Grille Fab
A1: Colonne 1 | B1: Valeurs stats | C1: Modificateurs | D1: Valeurs max | E1: Valeurs avant buff/débuff | F1: Valeurs effectives | G1: Buffs/Débuffs | H1: Colonne 2 | K1: Maîtrise | L1: Catégorie d'arme | M1: Dégâts | P1: Runes | Q1: Agression +20 AD
A2: HP | B2: ='Stats Fab'!G2 -> 520 | D2: =B2+C2 -> 520 | E2: 0 | F2: 0 | G2: Miraculé (+50% Soins/Bouclier) | H2: FALSE | K2: TRUE | L2: Arbalète légère | M2: 250 | Q2: Mobilité +1MS +1JA
A3: Mana | B3: ='Stats Fab'!G4 -> 180 | D3: =B3+C3 -> 180 | E3: 100 | F3: 100 | G3: Hémorragie (-50% Soins/Bouclier) | H3: FALSE | J3: Physique | K3: Physique | L3: 2H
A4: Bouclier | G4: Brisé (-50% Armure) | H4: FALSE | K4: Portée | L4: 5
G5: Choc magique (-50% Rés. Mag.) | H5: FALSE
A6: AD | B6: ='Stats Fab'!G6 -> 155 | C6: 20 | D6: =B6+C6 -> 175 | E6: 250 | F6: 250 | G6: Anéanti (-50% Armure & Rés. Mag.) | H6: FALSE | J6: Niveau | K6: 2
A7: AP | B7: ='Stats Fab'!G8 -> 55 | D7: =B7+C7 -> 55 | E7: 55 | F7: 55 | G7: Affaiblissement (-50% AD) | H7: FALSE | J7: Stack passif | K7: 5 | L7: (Penser à reset manuellement le stack après un full reset ou reset AD)
G8: Érosion magique (-50% AP) | H8: FALSE | J8: Dégâts/Soin Comp. 1 | K8: 250 | L8: 12
A9: Armure | B9: ='Stats Fab'!G10 -> 45 | D9: =B9+C9 -> 45 | E9: 45 | F9: 45 | G9: Épuisement (-50% AD/AP) | H9: FALSE | J9: Dégâts Comp. 2 | K9: 285
A10: Rés. Mag. | B10: ='Stats Fab'!G12 -> 22 | D10: =B10+C10 -> 22 | E10: 22 | F10: 22 | G10: Peau de fer (+50% Armure) | H10: FALSE | J10: Dégâts Comp. 3 | K10: 287
G11: Esprit d'acier(+50% Rés. Mag. | H11: FALSE | J11: Dégâts/soin Comp. 4 | K11: 150 | L11: 30
A12: % Critique | B12: ='Stats Fab'!G14 -> 25 | D12: =B12+C12 -> 25 | E12: 25 | F12: 25 | G12: Inflexible (+50% Armure & Rés. Mag.) | H12: FALSE
A13: % Dégâts critique | B13: ='Stats Fab'!G16 -> 180 | D13: =B13+C13 -> 180 | E13: 180 | G13: Bravoure (+50% AD) | H13: FALSE
A14: Type de léthalité | B14: 0 = pas de léthalité | C14: 1=léthalité physique | D14: 2=léthalité magique | E14: 3=léthalité phys. et mag. | F14: 0 | G14: Foi (+50% AP) | H14: FALSE
A15: % Vol de vie | D15: =B15+C15 -> 0 | E15: 0 | G15: Héroïsme (+50% AP/AD) | H15: FALSE
A16: % Sapience | B16: ='Stats Fab'!G18 -> 10 | D16: =B16+C16 -> 10 | E16: 10 | G16: Aiguisage (% Crit doublé) | H16: FALSE
A17: % Omnivamp | D17: =B17+C17 -> 0 | E17: 0
A23: Inventaire : | B23: Catégorie d'objet | C23: Nom d'objet | D23: Quantité | E23: Commentaires
B24: Équipement | C24: Arbalète légère | D24: 1 | E24: 25 pa
B25: Équipement | C25: Dague (dans sa botte) | D25: 1 | E25: 1 pa
B26: Équipement | C26: Hachette (arme secondaire) | D26: 1 | E26: Brisage/Mini-arme 1 pa
B27: Consommables | C27: Potion soin mineur | D27: 1 | E27: Rend (15 + 15%) HP
B28: Consommables | C28: Potion mana mineur | D28: 1 | E28: Rend (10 + 10%) Mana
B29: Butin | C29: Pièces de platine (pp) | D29: 0
B30: Butin | C30: 10 pièces d'or | D30: 1
B31: Butin | C31: 10 pièces d'argent | D31: 1
B32: Butin | C32: 10 pièces de cuivre | D32: 1
B33: Butin | C33: Tricorne | D33: 1 | E33: Valeur d'une pièce d'or (sentimental)
B34: Butin | C34: Boussole | D34: 1 | E34: 1 pa
B35: Butin | C35: Carte | D35: 1 | E35: N/A
B36: Butin | C36: Gourde | D36: 1 | E36: 10 pc
